<?xml version="1.0" ?>
<!-- =================================================================================== -->
<!-- |    This document was autogenerated by xacro from nv0_1.xacro                    | -->
<!-- |    EDITING THIS FILE BY HAND IS NOT RECOMMENDED                                 | -->
<!-- =================================================================================== -->
<robot name="enesbot_dualarm_v0.1" xmlns:xacro="http://www.ros.org/wiki/xacro">
  <link name="map">
    <visual>
      <geometry>
        <mesh filename="package://enesbot_dualarm/meshes/v0_1/nv01base.stl"/>
      </geometry>
    </visual>
  </link>
  <joint name="jr1" type="continuous">
    <parent link="map"/>
    <child link="r1"/>
    <origin rpy="0 -0.523599 -0.523599" xyz="0 -0.15 0.4"/>
    <axis xyz="1 0 0"/>
  </joint>
  <link name="r1">
    <visual>
      <geometry>
        <mesh filename="package://enesbot_dualarm/meshes/v0_1/nv01_1.stl"/>
      </geometry>
    </visual>
  </link>
  <joint name="jr2" type="continuous">
    <parent link="r1"/>
    <child link="r2"/>
    <origin rpy="0 0 0" xyz="0.1 0 0"/>
    <axis xyz="0 0 1"/>
  </joint>
  <link name="r2">
    <visual>
      <geometry>
        <mesh filename="package://enesbot_dualarm/meshes/v0_1/nv01_0.stl"/>
      </geometry>
    </visual>
  </link>
  <joint name="jr3" type="continuous">
    <parent link="r2"/>
    <child link="r3"/>
    <origin rpy="0 0 0" xyz="0.1 0 0"/>
    <axis xyz="1 0 0"/>
  </joint>
  <link name="r3">
    <visual>
      <geometry>
        <mesh filename="package://enesbot_dualarm/meshes/v0_1/nv01_1.stl"/>
      </geometry>
    </visual>
  </link>
  <joint name="jr4" type="continuous">
    <parent link="r3"/>
    <child link="r4"/>
    <origin rpy="0 0 0" xyz="0.1 0 0"/>
    <axis xyz="0 0 1"/>
  </joint>
  <link name="r4">
    <visual>
      <geometry>
        <mesh filename="package://enesbot_dualarm/meshes/v0_1/nv01_0.stl"/>
      </geometry>
    </visual>
  </link>
  <joint name="jr5" type="continuous">
    <parent link="r4"/>
    <child link="r5"/>
    <origin rpy="0 0 0" xyz="0.1 0 0"/>
    <axis xyz="1 0 0"/>
  </joint>
  <link name="r5">
    <visual>
      <geometry>
        <mesh filename="package://enesbot_dualarm/meshes/v0_1/nv01_1.stl"/>
      </geometry>
    </visual>
  </link>
  <joint name="jr6" type="continuous">
    <parent link="r5"/>
    <child link="r6"/>
    <origin rpy="0 0 0" xyz="0.1 0 0"/>
    <axis xyz="0 0 1"/>
  </joint>
  <link name="r6">
    <visual>
      <geometry>
        <mesh filename="package://enesbot_dualarm/meshes/v0_1/nv01_0.stl"/>
      </geometry>
    </visual>
  </link>
  <joint name="jr7" type="continuous">
    <parent link="r6"/>
    <child link="r7"/>
    <origin rpy="0 0 0" xyz="0.1 0 0"/>
    <axis xyz="1 0 0"/>
  </joint>
  <link name="r7">
    <visual>
      <geometry>
        <mesh filename="package://enesbot_dualarm/meshes/v0_1/nv01_2.stl"/>
      </geometry>
      <material name="white">
        <color rgba="1 1 1 1"/>
      </material>
    </visual>
  </link>
  <joint name="jl1" type="continuous">
    <parent link="map"/>
    <child link="l1"/>
    <origin rpy="0 -0.523599 0.523599" xyz="0 0.15 0.4"/>
    <axis xyz="1 0 0"/>
  </joint>
  <link name="l1">
    <visual>
      <geometry>
        <mesh filename="package://enesbot_dualarm/meshes/v0_1/nv01_1.stl"/>
      </geometry>
    </visual>
  </link>
  <joint name="jl2" type="continuous">
    <parent link="l1"/>
    <child link="l2"/>
    <origin rpy="0 0 0" xyz="0.1 0 0"/>
    <axis xyz="0 0 1"/>
  </joint>
  <link name="l2">
    <visual>
      <geometry>
        <mesh filename="package://enesbot_dualarm/meshes/v0_1/nv01_0.stl"/>
      </geometry>
    </visual>
  </link>
  <joint name="jl3" type="continuous">
    <parent link="l2"/>
    <child link="l3"/>
    <origin rpy="0 0 0" xyz="0.1 0 0"/>
    <axis xyz="1 0 0"/>
  </joint>
  <link name="l3">
    <visual>
      <geometry>
        <mesh filename="package://enesbot_dualarm/meshes/v0_1/nv01_1.stl"/>
      </geometry>
    </visual>
  </link>
  <joint name="jl4" type="continuous">
    <parent link="l3"/>
    <child link="l4"/>
    <origin rpy="0 0 0" xyz="0.1 0 0"/>
    <axis xyz="0 0 1"/>
  </joint>
  <link name="l4">
    <visual>
      <geometry>
        <mesh filename="package://enesbot_dualarm/meshes/v0_1/nv01_0.stl"/>
      </geometry>
    </visual>
  </link>
  <joint name="jl5" type="continuous">
    <parent link="l4"/>
    <child link="l5"/>
    <origin rpy="0 0 0" xyz="0.1 0 0"/>
    <axis xyz="1 0 0"/>
  </joint>
  <link name="l5">
    <visual>
      <geometry>
        <mesh filename="package://enesbot_dualarm/meshes/v0_1/nv01_1.stl"/>
      </geometry>
    </visual>
  </link>
  <joint name="jl6" type="continuous">
    <parent link="l5"/>
    <child link="l6"/>
    <origin rpy="0 0 0" xyz="0.1 0 0"/>
    <axis xyz="0 0 1"/>
  </joint>
  <link name="l6">
    <visual>
      <geometry>
        <mesh filename="package://enesbot_dualarm/meshes/v0_1/nv01_0.stl"/>
      </geometry>
    </visual>
  </link>
  <joint name="jl7" type="continuous">
    <parent link="l6"/>
    <child link="l7"/>
    <origin rpy="0 0 0" xyz="0.1 0 0"/>
    <axis xyz="1 0 0"/>
  </joint>
  <link name="l7">
    <visual>
      <geometry>
        <mesh filename="package://enesbot_dualarm/meshes/v0_1/nv01_2.stl"/>
      </geometry>
      <material name="white">
        <color rgba="1 1 1 1"/>
      </material>
    </visual>
  </link>
</robot>

